Workbook

Sheet 分類
B1: Q | C1: R | D1: S | E1: T | F1: U | G1: V | H1: ER | I1: Ｘ | P1: Ｃ | Q1: Ｄ | R1: E | V1: Ｆ | AG1: Ｇ | AK1: Ｊ | AL1: Ｋ | AM1: AE値ｺﾋﾟｰ | AN1: Ｚ | AS1: AJ値ｺﾋﾟｰ | AU1: AO値ｺﾋﾟｰ | AW1: AS値ｺﾋﾟｰ | AZ1: AY値ｺﾋﾟｰ | BK1: Ｍ | BL1: Ｎ | BU1: ER※確認 | BV1: ET※確認 | BW1: EW※確認 | BX1: EX※確認 | BY1: FB
B2: 大分類 | D2: 中分類 | F2: 小分類 | I2: 常時 | J2: 価格表 | P2: ﾒｰｶｰ | R2: 商品ｺｰﾄﾞ：機工ﾏｽﾀｰ表示 | V2: 商品名：機工ﾏｽﾀｰ表示 | AG2: 規格・寸法：機工ﾏｽﾀｰ表示 | AK2: 単位 | AM2: 機工ﾏｽﾀｰ | AS2: 小箱 | AU2: バラ | BK2: 価格ﾍﾞｰｽ仕入先 | BN2: 仕入先候補① | BP2: 仕入先候補② | BR2: 価格改定日 | BU2: 在庫取寄区分 | BV2: 倉庫CD | BW2: 在庫評価区分名 | BX2: 在庫評価単価 | BY2: 棚番 | BZ2: ｽﾄｯｸ場所
A3: 提出 | I3: ﾄﾘﾖｾ | J3: 見出 | L3: ﾍﾟｰｼﾞ | P3: ｺｰﾄﾞ | Q3: ﾒｰｶｰ | R3: 半角33 | V3: 半角40 | AG3: 半角30 | AK3: 機工ﾏｽﾀｰ表示 | AM3: 表示 | AO3: 定価 | AP3: 仕入＠ | AQ3: T | AS3: 安い | AU3: 高い | BR3: 現 | BS3: 予定 | BT3: 仕入先情報 | BU3: 半角1 | BV3: 半角3 | BW3: 自社標準 | BY3: 半角10
B4: ｺｰﾄﾞ | C4: 分類名 | D4: ｺｰﾄﾞ | E4: 分類名 | F4: ｺｰﾄﾞ | G4: 分類名 | H4: ｺｰﾄﾞ | I4: 売切 | J4: № | L4: № | M4: № | N4: № | O4: № | P4: 123546 | Q4: 略称 | R4: 12345678901234567890123 | S4: ｺｰﾄﾞ① | T4: ｺｰﾄﾞ② | U4: ｺｰﾄﾞ③ | V4: 1234567890123456789012345678901234567890 | W4: ﾒｰｶｰ名 | X4: 材質 | Y4: 商品名 | Z4: 商品名④ | AA4: 商品名⑤ | AB4: 商品名⑥ | AC4: 商品名⑦ | AD4: 商品名⑧ | AE4: 商品名⑨ | AF4: 商品名⑩ | AG4: 123456789012345678901234567890 | AH4: 規格寸法① | AI4: 規格寸法② | AJ4: 規格寸法③ | AK4: ｺｰﾄﾞ | AL4: 単位名 | AM4: 仕入＠ | AN4: 定価 | AO4: 掛率 | AP4: 掛率 | AQ4: N | AR4: ① | AS4: 売上＠① | AT4: ② | AU4: 売上＠② | AV4: 特定 | AW4: 特定＠① | AX4: 特値先 | AY4: 特定 | AZ4: 特定＠② | BA4: 特値先 | BB4: 特定 | BC4: 特定＠③ | BD4: 特値先 | BE4: 特定 | BF4: 特定＠④ | BG4: 特値先 | BH4: 特定 | BI4: 特定＠④ | BJ4: 特値先 | BK4: ｺｰﾄﾞ | BL4: 仕入先名 | BM4: 定価引用先 | BN4: ｺｰﾄﾞ | BO4: 仕入先名 | BP4: ｺｰﾄﾞ | BQ4: 仕入先名 | BR4: 現設定日 | BS4: 価格改訂日 | BT4: メモ | BY4: 1234568790
A5: ✓ | B5: T14 | C5: =IF(B5="","",_xlfn.XLOOKUP(B5,大分類!$A:$A,大分類!$B:$B,0)) -> ｸﾞﾘｽﾆｯﾌﾟﾙ | D5: T19 | E5: =IF(D5="","",_xlfn.XLOOKUP(D5,中分類!$A:$A,中分類!$B:$B,0)) -> ﾒｯｷ | F5: T51 | G5: =IF(F5="","",_xlfn.XLOOKUP(F5,小分類!$A:$A,小分類!$B:$B,0)) -> ﾘﾘｰﾌﾆｯﾌﾟﾙ | H5: 1 | I5: =IF(H5="","",_xlfn.XLOOKUP(H5,在庫取寄区分!$A:$A,在庫取寄区分!$B:$B,0)) -> 常時在庫品 | J5: P | K5: 23 | L5: 3 | P5: 963161 | Q5: =IF(P5="","",_xlfn.XLOOKUP(P5,ﾒｰｶｰCD!$A:$A,ﾒｰｶｰCD!$B:$B,0)) -> ﾌﾛｰﾊﾞﾙ | R5: =S5&T5&U5 -> MRRFNI1/8 | S5: MRRFNI | T5: 1/8 | V5: =W5&" "&X5&" "&Y5&" "&Z5&" "&AA5&" "&AB5&" "&AC5&" "&AD5&AE5&AF5 -> 黄銅ﾒｯｷ付 ﾘﾘｰﾌﾆｯﾌﾟﾙ PT1/8 | X5: 黄銅ﾒｯｷ付 | Y5: ﾘﾘｰﾌﾆｯﾌﾟﾙ | Z5: PT1/8 | AG5: =AH5&" "&AI5&" "&AJ5 -> 33201601 NRN-01K | AH5: 33201601 | AI5: NRN-01K | AK5: 01 | AL5: =IF(AK5="","",_xlfn.XLOOKUP(AK5,単位CD!$A:$A,単位CD!$B:$B,0)) -> ヶ | AM5: =ROUND(AN5*AO5,0) -> 172 | AN5: 330 | AO5: 0.52 | AP5: =ROUND(AM5/AN5,3) -> 0.521 | AQ5: T | AS5: =IF($AQ5="T",ROUND($AN5*AR5,0),ROUND($AM5*AR5,0)) -> 0 | AT5: 0.78 | AU5: =IF($AQ5="T",ROUND($AN5*AT5,0),ROUND($AM5*AT5,0)) -> 257 | AW5: =IF($AQ5="T",ROUND($AN5*AV5,0),ROUND($AM5*AV5,0)) -> 0 | AX5: =COUNTIFS(特値先!$A:$A,分類!AV5) -> 0 | AZ5: =IF($AQ5="T",ROUND($AN5*AY5,0),ROUND($AM5*AY5,0)) -> 0 | BA5: =COUNTIFS(特値先!$A:$A,分類!AY5) -> 0 | BC5: =ROUND(AN5*BB5,0) -> 0 | BF5: =IF($AQ5="T",ROUND($AN5*BE5,0),ROUND($AM5*BE5,0)) -> 0 | BG5: =COUNTIFS(特値先!$A:$A,分類!BE5) -> 0 | BI5: =IF($AQ5="T",ROUND($AN5*BH5,0),ROUND($AM5*BH5,0)) -> 0 | BJ5: =COUNTIFS(特値先!$A:$A,分類!BH5) -> 0 | BK5: 15 | BL5: =IF(BK5="","",_xlfn.XLOOKUP(BK5,仕入先CD!$A:$A,仕入先CD!$B:$B,0)) -> ﾌﾛｰﾊﾞﾙ | BM5: らくねっと | BO5: =IF(BN5="","",_xlfn.XLOOKUP(BN5,仕入先CD!$A:$A,仕入先CD!$B:$B,0)) | BQ5: =IF(BP5="","",_xlfn.XLOOKUP(BP5,仕入先CD!$A:$A,仕入先CD!$B:$B,0)) | BR5: 45992
A6: ✓ | B6: T14 | C6: =IF(B6="","",_xlfn.XLOOKUP(B6,大分類!$A:$A,大分類!$B:$B,0)) -> ｸﾞﾘｽﾆｯﾌﾟﾙ | D6: T19 | E6: =IF(D6="","",_xlfn.XLOOKUP(D6,中分類!$A:$A,中分類!$B:$B,0)) -> ﾒｯｷ | F6: T51 | G6: =IF(F6="","",_xlfn.XLOOKUP(F6,小分類!$A:$A,小分類!$B:$B,0)) -> ﾘﾘｰﾌﾆｯﾌﾟﾙ | H6: 1 | I6: =IF(H6="","",_xlfn.XLOOKUP(H6,在庫取寄区分!$A:$A,在庫取寄区分!$B:$B,0)) -> 常時在庫品 | J6: P | K6: 23 | L6: 3 | P6: 963161 | Q6: =IF(P6="","",_xlfn.XLOOKUP(P6,ﾒｰｶｰCD!$A:$A,ﾒｰｶｰCD!$B:$B,0)) -> ﾌﾛｰﾊﾞﾙ | R6: =S6&T6&U6 -> MRRFNI1/4 | S6: MRRFNI | T6: 1/4 | V6: =W6&" "&X6&" "&Y6&" "&Z6&" "&AA6&" "&AB6&" "&AC6&" "&AD6&AE6&AF6 -> 黄銅ﾒｯｷ付 ﾘﾘｰﾌﾆｯﾌﾟﾙ PT1/4 | X6: 黄銅ﾒｯｷ付 | Y6: ﾘﾘｰﾌﾆｯﾌﾟﾙ | Z6: PT1/4 | AG6: =AH6&" "&AI6&" "&AJ6 -> 33201602 NRN-02K | AH6: 33201602 | AI6: NRN-02K | AK6: 01 | AL6: =IF(AK6="","",_xlfn.XLOOKUP(AK6,単位CD!$A:$A,単位CD!$B:$B,0)) -> ヶ | AM6: =ROUND(AN6*AO6,0) -> 281 | AN6: 540 | AO6: 0.52 | AP6: =ROUND(AM6/AN6,3) -> 0.52 | AQ6: T | AS6: =IF($AQ6="T",ROUND($AN6*AR6,0),ROUND($AM6*AR6,0)) -> 0 | AT6: 0.78 | AU6: =IF($AQ6="T",ROUND($AN6*AT6,0),ROUND($AM6*AT6,0)) -> 421 | AW6: =IF($AQ6="T",ROUND($AN6*AV6,0),ROUND($AM6*AV6,0)) -> 0 | AX6: =COUNTIFS(特値先!$A:$A,分類!AV6) -> 0 | AZ6: =IF($AQ6="T",ROUND($AN6*AY6,0),ROUND($AM6*AY6,0)) -> 0 | BA6: =COUNTIFS(特値先!$A:$A,分類!AY6) -> 0 | BC6: =ROUND(AN6*BB6,0) -> 0 | BF6: =IF($AQ6="T",ROUND($AN6*BE6,0),ROUND($AM6*BE6,0)) -> 0 | BG6: =COUNTIFS(特値先!$A:$A,分類!BE6) -> 0 | BI6: =IF($AQ6="T",ROUND($AN6*BH6,0),ROUND($AM6*BH6,0)) -> 0 | BJ6: =COUNTIFS(特値先!$A:$A,分類!BH6) -> 0 | BK6: 15 | BL6: =IF(BK6="","",_xlfn.XLOOKUP(BK6,仕入先CD!$A:$A,仕入先CD!$B:$B,0)) -> ﾌﾛｰﾊﾞﾙ | BM6: らくねっと | BO6: =IF(BN6="","",_xlfn.XLOOKUP(BN6,仕入先CD!$A:$A,仕入先CD!$B:$B,0)) | BQ6: =IF(BP6="","",_xlfn.XLOOKUP(BP6,仕入先CD!$A:$A,仕入先CD!$B:$B,0)) | BR6: 45992
A7: ✓ | B7: T14 | C7: =IF(B7="","",_xlfn.XLOOKUP(B7,大分類!$A:$A,大分類!$B:$B,0)) -> ｸﾞﾘｽﾆｯﾌﾟﾙ | D7: T19 | E7: =IF(D7="","",_xlfn.XLOOKUP(D7,中分類!$A:$A,中分類!$B:$B,0)) -> ﾒｯｷ | F7: T51 | G7: =IF(F7="","",_xlfn.XLOOKUP(F7,小分類!$A:$A,小分類!$B:$B,0)) -> ﾘﾘｰﾌﾆｯﾌﾟﾙ | H7: 1 | I7: =IF(H7="","",_xlfn.XLOOKUP(H7,在庫取寄区分!$A:$A,在庫取寄区分!$B:$B,0)) -> 常時在庫品 | J7: P | K7: 23 | L7: 3 | P7: 963161 | Q7: =IF(P7="","",_xlfn.XLOOKUP(P7,ﾒｰｶｰCD!$A:$A,ﾒｰｶｰCD!$B:$B,0)) -> ﾌﾛｰﾊﾞﾙ | R7: =S7&T7&U7 -> MRRFNI3/8 | S7: MRRFNI | T7: 3/8 | V7: =W7&" "&X7&" "&Y7&" "&Z7&" "&AA7&" "&AB7&" "&AC7&" "&AD7&AE7&AF7 -> 黄銅ﾒｯｷ付 ﾘﾘｰﾌﾆｯﾌﾟﾙ PT3/8 | X7: 黄銅ﾒｯｷ付 | Y7: ﾘﾘｰﾌﾆｯﾌﾟﾙ | Z7: PT3/8 | AG7: =AH7&" "&AI7&" "&AJ7 -> 33201603 NRN-03K | AH7: 33201603 | AI7: NRN-03K | AK7: 01 | AL7: =IF(AK7="","",_xlfn.XLOOKUP(AK7,単位CD!$A:$A,単位CD!$B:$B,0)) -> ヶ | AM7: =ROUND(AN7*AO7,0) -> 463 | AN7: 890 | AO7: 0.52 | AP7: =ROUND(AM7/AN7,3) -> 0.52 | AQ7: T | AS7: =IF($AQ7="T",ROUND($AN7*AR7,0),ROUND($AM7*AR7,0)) -> 0 | AT7: 0.78 | AU7: =IF($AQ7="T",ROUND($AN7*AT7,0),ROUND($AM7*AT7,0)) -> 694 | AW7: =IF($AQ7="T",ROUND($AN7*AV7,0),ROUND($AM7*AV7,0)) -> 0 | AX7: =COUNTIFS(特値先!$A:$A,分類!AV7) -> 0 | AZ7: =IF($AQ7="T",ROUND($AN7*AY7,0),ROUND($AM7*AY7,0)) -> 0 | BA7: =COUNTIFS(特値先!$A:$A,分類!AY7) -> 0 | BC7: =ROUND(AN7*BB7,0) -> 0 | BF7: =IF($AQ7="T",ROUND($AN7*BE7,0),ROUND($AM7*BE7,0)) -> 0 | BG7: =COUNTIFS(特値先!$A:$A,分類!BE7) -> 0 | BI7: =IF($AQ7="T",ROUND($AN7*BH7,0),ROUND($AM7*BH7,0)) -> 0 | BJ7: =COUNTIFS(特値先!$A:$A,分類!BH7) -> 0 | BK7: 15 | BL7: =IF(BK7="","",_xlfn.XLOOKUP(BK7,仕入先CD!$A:$A,仕入先CD!$B:$B,0)) -> ﾌﾛｰﾊﾞﾙ | BM7: らくねっと | BO7: =IF(BN7="","",_xlfn.XLOOKUP(BN7,仕入先CD!$A:$A,仕入先CD!$B:$B,0)) | BQ7: =IF(BP7="","",_xlfn.XLOOKUP(BP7,仕入先CD!$A:$A,仕入先CD!$B:$B,0)) | BR7: 45992

Sheet 特値先
A1: 特値先別掛率 | B1: 特値先ｺｰﾄﾞ | C1: 特値先
C2: =IF(B2="","",_xlfn.XLOOKUP(B2,お客様CD!$A:$A,お客様CD!$B:$B,"",0))
C3: =IF(B3="","",_xlfn.XLOOKUP(B3,お客様CD!$A:$A,お客様CD!$B:$B,"",0))
C4: =IF(B4="","",_xlfn.XLOOKUP(B4,お客様CD!$A:$A,お客様CD!$B:$B,"",0))
C5: =IF(B5="","",_xlfn.XLOOKUP(B5,お客様CD!$A:$A,お客様CD!$B:$B,"",0))
C6: =IF(B6="","",_xlfn.XLOOKUP(B6,お客様CD!$A:$A,お客様CD!$B:$B,"",0))
C7: =IF(B7="","",_xlfn.XLOOKUP(B7,お客様CD!$A:$A,お客様CD!$B:$B,"",0))
C8: =IF(B8="","",_xlfn.XLOOKUP(B8,お客様CD!$A:$A,お客様CD!$B:$B,"",0))
C9: =IF(B9="","",_xlfn.XLOOKUP(B9,お客様CD!$A:$A,お客様CD!$B:$B,"",0))
C10: =IF(B10="","",_xlfn.XLOOKUP(B10,お客様CD!$A:$A,お客様CD!$B:$B,"",0))
C11: =IF(B11="","",_xlfn.XLOOKUP(B11,お客様CD!$A:$A,お客様CD!$B:$B,"",0))
C12: =IF(B12="","",_xlfn.XLOOKUP(B12,お客様CD!$A:$A,お客様CD!$B:$B,"",0))
C13: =IF(B13="","",_xlfn.XLOOKUP(B13,お客様CD!$A:$A,お客様CD!$B:$B,"",0))
... C822: =IF(B822="","",_xlfn.XLOOKUP(B822,お客様CD!$A:$A,お客様CD!$B:$B,"",0))

Sheet 提出用書式
A1: 商社CD | B1: 商社略称 | C1: ﾒｰｶｰCD | D1: ﾒｰｶｰ略称 | E1: 商品CD | F1: 商品名 | G1: 規格・寸法 | H1: 商品名ｶﾅ | I1: JANCD | J1: 単位CD | K1: 単位名 | L1: 入数 | M1: 標準仕入先CD | N1: 標準仕入先名 | O1: 分類商社CD | P1: 分類商社略称 | Q1: 大分類CD | R1: 大分類名 | S1: 中分類CD | T1: 中分類名 | U1: 小分類CD | V1: 小分類名 | W1: 詳細分類CD | X1: 詳細分類名 | Y1: 価格名称 | Z1: 定価(税抜) | AA1: 定価(税込) | AB1: 定価(掛率基準) | AC1: 定価(掛率) | AD1: 価格1名称 | AE1: 価格1(税抜) | AF1: 価格1(税込) | AG1: 価格1(掛率基準) | AH1: 価格1(掛率) | AI1: 価格2名称 | AJ1: 価格2(税抜) | AK1: 価格2(税込) | AL1: 価格2(掛率基準) | AM1: 価格2(掛率) | AN1: 価格3名称 | AO1: 価格3(税抜) | AP1: 価格3(税込) | AQ1: 価格3(掛率基準) | AR1: 価格3(掛率) | AS1: 価格4名称 | AT1: 価格4(税抜) | AU1: 価格4(税込) | AV1: 価格4(掛率基準) | AW1: 価格4(掛率) | AX1: 価格5名称 | AY1: 価格5(税抜) | AZ1: 価格5(税込) | BA1: 価格5(掛率基準) | BB1: 価格5(掛率) | BC1: 価格6名称 | BD1: 価格6(税抜) | BE1: 価格6(税込) | BF1: 価格6(掛率基準) | BG1: 価格6(掛率) | BH1: 価格7名称 | BI1: 価格7(税抜) | BJ1: 価格7(税込) | BK1: 価格7(掛率基準) | BL1: 価格7(掛率) | BM1: 価格8名称 | BN1: 価格8(税抜) | BO1: 価格8(税込) | BP1: 価格8(掛率基準) | BQ1: 価格8(掛率) | BR1: 価格9名称 | BS1: 価格9(税抜) | BT1: 価格9(税込) | BU1: 価格9(掛率基準) | BV1: 価格9(掛率) | BW1: (新)定価(適用日) | BX1: (新)定価(税抜) | BY1: (新)定価(税込) | BZ1: (新)定価(掛率基準) | CA1: (新)定価(掛率) | CB1: (新)価格1(適用日) | CC1: (新)価格1(税抜) | CD1: (新)価格1(税込) | CE1: (新)価格1(掛率基準) | CF1: (新)価格1(掛率) | CG1: (新)価格2(適用日) | CH1: (新)価格2(税抜) | CI1: (新)価格2(税込) | CJ1: (新)価格2(掛率基準) | CK1: (新)価格2(掛率) | CL1: (新)価格3(適用日) | CM1: (新)価格3(税抜) | CN1: (新)価格3(税込) | CO1: (新)価格3(掛率基準) | CP1: (新)価格3(掛率) | CQ1: (新)価格4(適用日) | CR1: (新)価格4(税抜) | CS1: (新)価格4(税込) | CT1: (新)価格4(掛率基準) | CU1: (新)価格4(掛率) | CV1: (新)価格5(適用日) | CW1: (新)価格5(税抜) | CX1: (新)価格5(税込) | CY1: (新)価格5(掛率基準) | CZ1: (新)価格5(掛率) | DA1: (新)価格6(適用日) | DB1: (新)価格6(税抜) | DC1: (新)価格6(税込) | DD1: (新)価格6(掛率基準) | DE1: (新)価格6(掛率) | DF1: (新)価格7(適用日) | DG1: (新)価格7(税抜) | DH1: (新)価格7(税込) | DI1: (新)価格7(掛率基準) | DJ1: (新)価格7(掛率) | DK1: (新)価格8(適用日) | DL1: (新)価格8(税抜) | DM1: (新)価格8(税込) | DN1: (新)価格8(掛率基準) | DO1: (新)価格8(掛率) | DP1: (新)価格9(適用日) | DQ1: (新)価格9(税抜) | DR1: (新)価格9(税込) | DS1: (新)価格9(掛率基準) | DT1: (新)価格9(掛率) | DU1: 層別 | DV1: 等級管理区分 | DW1: 等級管理区分名 | DX1: 商品諸口区分 | DY1: 商品諸口区分名 | DZ1: 課税区分 | EA1: 課税区分名 | EB1: 計算区分 | EC1: 計算区分名 | ED1: 商品属性1 | EE1: 商品属性2 | EF1: 商品属性3 | EG1: 商品属性4 | EH1: 商品属性5 | EI1: 数量目標 | EJ1: 売上目標 | EK1: 粗利目標 | EL1: 集計ｷｰ1 | EM1: 集計ｷｰ2 | EN1: 表示順位 | EO1: 取扱開始日 | EP1: 取扱終了日 | EQ1: 商品ﾒﾓ | ER1: 在庫取寄区分 | ES1: 在庫取寄区分名 | ET1: 倉庫CD | EU1: 倉庫名 | EV1: 在庫評価区分 | EW1: 在庫評価区分名 | EX1: 在庫評価単価 | EY1: 発注区分 | EZ1: 発注区分名 | FA1: 商品掛率ｸﾞﾙｰﾌﾟ | FB1: 棚番
A2: 半角数字(8) | C2: 半角数字(6) | E2: ★半角(33) | F2: ★全角(40) | G2: 全角(30) | H2: 半角(20) | I2: 半角(20) | J2: 半角数字(2) | L2: 半角数値(6.2) | M2: 半角数字(8) | O2: 半角数字(8) | Q2: 半角(6) | S2: 半角(6) | U2: 半角(6) | W2: 半角(6) | Z2: 半角数値(8.2) | AA2: 半角数値(8.2) | AB2: 半角数字(2) | AC2: 半角数値(3.2) | AE2: 半角数値(8.2) | AF2: 半角数値(8.2) | AG2: 半角数字(2) | AH2: 半角数値(3.2) | AJ2: 半角数値(8.2) | AK2: 半角数値(8.2) | AL2: 半角数字(2) | AM2: 半角数値(3.2) | AO2: 半角数値(8.2) | AP2: 半角数値(8.2) | AQ2: 半角数字(2) | AR2: 半角数値(3.2) | AT2: 半角数値(8.2) | AU2: 半角数値(8.2) | AV2: 半角数字(2) | AW2: 半角数値(3.2) | AY2: 半角数値(8.2) | AZ2: 半角数値(8.2) | BA2: 半角数字(2) | BB2: 半角数値(3.2) | BD2: 半角数値(8.2) | BE2: 半角数値(8.2) | BF2: 半角数字(2) | BG2: 半角数値(3.2) | BI2: 半角数値(8.2) | BJ2: 半角数値(8.2) | BK2: 半角数字(2) | BL2: 半角数値(3.2) | BN2: 半角数値(8.2) | BO2: 半角数値(8.2) | BP2: 半角数字(2) | BQ2: 半角数値(3.2) | BS2: 半角数値(8.2) | BT2: 半角数値(8.2) | BU2: 半角数字(2) | BV2: 半角数値(3.2) | BW2: 半角日付(10) | BX2: 半角数値(8.2) | BY2: 半角数値(8.2) | BZ2: 半角数字(2) | CA2: 半角数値(3.2) | CB2: 半角日付(10) | CC2: 半角数値(8.2) | CD2: 半角数値(8.2) | CE2: 半角数字(2) | CF2: 半角数値(3.2) | CG2: 半角日付(10) | CH2: 半角数値(8.2) | CI2: 半角数値(8.2) | CJ2: 半角数字(2) | CK2: 半角数値(3.2) | CL2: 半角日付(10) | CM2: 半角数値(8.2) | CN2: 半角数値(8.2) | CO2: 半角数字(2) | CP2: 半角数値(3.2) | CQ2: 半角日付(10) | CR2: 半角数値(8.2) | CS2: 半角数値(8.2) | CT2: 半角数字(2) | CU2: 半角数値(3.2) | CV2: 半角日付(10) | CW2: 半角数値(8.2) | CX2: 半角数値(8.2) | CY2: 半角数字(2) | CZ2: 半角数値(3.2) | DA2: 半角日付(10) | DB2: 半角数値(8.2) | DC2: 半角数値(8.2) | DD2: 半角数字(2) | DE2: 半角数値(3.2) | DF2: 半角日付(10) | DG2: 半角数値(8.2) | DH2: 半角数値(8.2) | DI2: 半角数字(2) | DJ2: 半角数値(3.2) | DK2: 半角日付(10) | DL2: 半角数値(8.2) | DM2: 半角数値(8.2) | DN2: 半角数字(2) | DO2: 半角数値(3.2) | DP2: 半角日付(10) | DQ2: 半角数値(8.2) | DR2: 半角数値(8.2) | DS2: 半角数字(2) | DT2: 半角数値(3.2) | DU2: 半角(6) | DV2: 半角数字(1) | DX2: 半角数字(1) | DZ2: 半角数字(2) | EB2: 半角数字(1) | ED2: 半角(1) | EE2: 半角(1) | EF2: 半角(1) | EG2: 半角(1) | EH2: 半角(1) | EI2: 半角数値(6.2) | EJ2: 半角数値(11) | EK2: 半角数値(11) | EL2: 半角(4) | EM2: 半角(4) | EN2: 半角数値(6.2) | EO2: 半角日付(10) | EP2: 半角日付(10) | EQ2: 全角(800) | ER2: 半角数字(1) | ET2: 半角数字(3) | EV2: 半角数字(1) | EX2: 半角数字(8.2) | EY2: 半角数字(2) | FA2: 半角(20) | FB2: 半角(10)
C3: 888888 | E3: SNI6 | F3: ｽﾃﾝﾚｽ ﾈｼﾞｺﾐ 両口ﾆｯﾌﾟﾙ 6A | G3: 04100901 | J3: 01 | L3: 1.00 | Z3: 280 | AD3: 仕切り | AE3: 84 | DV3: 0 | DW3: しない | DX3: 0 | DY3: 通常商品 | DZ3: 00 | EA3: 外税 | EB3: 0 | EC3: 通常 | ED3: 0 | EE3: 0 | EF3: 0 | EG3: 0 | EH3: 0 | EI3: 0.00 | EJ3: 0 | EK3: 0 | EN3: 10000.00 | ER3: 2 | ES3: 在庫品 | ET3: 001 | EU3: 本社倉庫 | EV3: 0 | EW3: 自社標準 | EX3: 0.00
C4: P | E4: R | F4: V | G4: AG | J4: AK | M4: BK | Q4: B | S4: D | U4: F | Z4: AN | AE4: AM | AJ4: AS | AO4: AU | AT4: AW | AY4: AZ | BD4: BC | BI4: BF | BN4: BI | ER4: H | ET4: BV | EW4: BW | EX4: BX | FB4: BY
C5: =IF(分類!P5="","",分類!P5) -> 963161 | D5: =IF(C5="","",_xlfn.XLOOKUP(C5,ﾒｰｶｰCD!$A:$A,ﾒｰｶｰCD!$B:$B,0)) -> ﾌﾛｰﾊﾞﾙ | E5: =IF(分類!R5="","",分類!R5) -> MRRFNI1/8 | F5: =IF(分類!V5="","",分類!V5) -> 黄銅ﾒｯｷ付 ﾘﾘｰﾌﾆｯﾌﾟﾙ PT1/8 | G5: =IF(分類!AG5="","",分類!AG5) -> 33201601 NRN-01K | J5: =IF(分類!AK5="","",分類!AK5) -> 01 | K5: =IF(J5="","",_xlfn.XLOOKUP(J5,単位CD!$A:$A,単位CD!$B:$B,0)) -> ヶ | M5: =IF(分類!BK5="","",分類!BK5) -> 15 | N5: =IF(M5="","",_xlfn.XLOOKUP(M5,仕入先CD!$A:$A,仕入先CD!$B:$B,0)) -> ﾌﾛｰﾊﾞﾙ | Q5: =IF(分類!B5="","",分類!B5) -> T14 | R5: =IF(Q5="","",_xlfn.XLOOKUP(Q5,大分類!$A:$A,大分類!$B:$B,0)) -> ｸﾞﾘｽﾆｯﾌﾟﾙ | S5: =IF(分類!D5="","",分類!D5) -> T19 | T5: =IF(S5="","",_xlfn.XLOOKUP(S5,中分類!$A:$A,中分類!$B:$B,0)) -> ﾒｯｷ | U5: =IF(分類!F5="","",分類!F5) -> T51 | V5: =IF(U5="","",_xlfn.XLOOKUP(U5,小分類!$A:$A,小分類!$B:$B,0)) -> ﾘﾘｰﾌﾆｯﾌﾟﾙ | Z5: =IF(分類!AN5="","",分類!AN5) -> 330 | AE5: =IF(分類!AM5="","",分類!AM5) -> 172 | AJ5: =IF(分類!AS5="","",分類!AS5) -> 0 | AO5: =IF(分類!AU5="","",分類!AU5) -> 257 | AT5: =IF(分類!AW5="","",分類!AW5) -> 0 | AY5: =IF(分類!AZ5="","",分類!AZ5) -> 0 | BD5: =IF(分類!BC5="","",分類!BC5) -> 0 | BI5: =IF(分類!BF5="","",分類!BF5) -> 0 | BN5: =IF(分類!BI5="","",分類!BI5) -> 0 | ER5: =IF(分類!H5="","",分類!H5) -> 1 | ES5: =IF(ER5="","",_xlfn.XLOOKUP(提出用書式!ER5,在庫取寄区分!$A:$A,在庫取寄区分!$B:$B,0)) -> 常時在庫品 | ET5: =IF(分類!BV5="","",分類!BV5) | EW5: =IF(分類!BW5="","",分類!BW5) | EX5: =IF(分類!BX5="","",分類!BX5) | FB5: =IF(分類!BY5="","",分類!BY5)
C6: =IF(分類!P6="","",分類!P6) -> 963161 | D6: =IF(C6="","",_xlfn.XLOOKUP(C6,ﾒｰｶｰCD!$A:$A,ﾒｰｶｰCD!$B:$B,0)) -> ﾌﾛｰﾊﾞﾙ | E6: =IF(分類!R6="","",分類!R6) -> MRRFNI1/4 | F6: =IF(分類!V6="","",分類!V6) -> 黄銅ﾒｯｷ付 ﾘﾘｰﾌﾆｯﾌﾟﾙ PT1/4 | G6: =IF(分類!AG6="","",分類!AG6) -> 33201602 NRN-02K | J6: =IF(分類!AK6="","",分類!AK6) -> 01 | K6: =IF(J6="","",_xlfn.XLOOKUP(J6,単位CD!$A:$A,単位CD!$B:$B,0)) -> ヶ | M6: =IF(分類!BK6="","",分類!BK6) -> 15 | N6: =IF(M6="","",_xlfn.XLOOKUP(M6,仕入先CD!$A:$A,仕入先CD!$B:$B,0)) -> ﾌﾛｰﾊﾞﾙ | Q6: =IF(分類!B6="","",分類!B6) -> T14 | R6: =IF(Q6="","",_xlfn.XLOOKUP(Q6,大分類!$A:$A,大分類!$B:$B,0)) -> ｸﾞﾘｽﾆｯﾌﾟﾙ | S6: =IF(分類!D6="","",分類!D6) -> T19 | T6: =IF(S6="","",_xlfn.XLOOKUP(S6,中分類!$A:$A,中分類!$B:$B,0)) -> ﾒｯｷ | U6: =IF(分類!F6="","",分類!F6) -> T51 | V6: =IF(U6="","",_xlfn.XLOOKUP(U6,小分類!$A:$A,小分類!$B:$B,0)) -> ﾘﾘｰﾌﾆｯﾌﾟﾙ | Z6: =IF(分類!AN6="","",分類!AN6) -> 540 | AE6: =IF(分類!AM6="","",分類!AM6) -> 281 | AJ6: =IF(分類!AS6="","",分類!AS6) -> 0 | AO6: =IF(分類!AU6="","",分類!AU6) -> 421 | AT6: =IF(分類!AW6="","",分類!AW6) -> 0 | AY6: =IF(分類!AZ6="","",分類!AZ6) -> 0 | BD6: =IF(分類!BC6="","",分類!BC6) -> 0 | BI6: =IF(分類!BF6="","",分類!BF6) -> 0 | BN6: =IF(分類!BI6="","",分類!BI6) -> 0 | ER6: =IF(分類!H6="","",分類!H6) -> 1 | ES6: =IF(ER6="","",_xlfn.XLOOKUP(提出用書式!ER6,在庫取寄区分!$A:$A,在庫取寄区分!$B:$B,0)) -> 常時在庫品 | ET6: =IF(分類!BV6="","",分類!BV6) | EW6: =IF(分類!BW6="","",分類!BW6) | EX6: =IF(分類!BX6="","",分類!BX6) | FB6: =IF(分類!BY6="","",分類!BY6)
C7: =IF(分類!P7="","",分類!P7) -> 963161 | D7: =IF(C7="","",_xlfn.XLOOKUP(C7,ﾒｰｶｰCD!$A:$A,ﾒｰｶｰCD!$B:$B,0)) -> ﾌﾛｰﾊﾞﾙ | E7: =IF(分類!R7="","",分類!R7) -> MRRFNI3/8 | F7: =IF(分類!V7="","",分類!V7) -> 黄銅ﾒｯｷ付 ﾘﾘｰﾌﾆｯﾌﾟﾙ PT3/8 | G7: =IF(分類!AG7="","",分類!AG7) -> 33201603 NRN-03K | J7: =IF(分類!AK7="","",分類!AK7) -> 01 | K7: =IF(J7="","",_xlfn.XLOOKUP(J7,単位CD!$A:$A,単位CD!$B:$B,0)) -> ヶ | M7: =IF(分類!BK7="","",分類!BK7) -> 15 | N7: =IF(M7="","",_xlfn.XLOOKUP(M7,仕入先CD!$A:$A,仕入先CD!$B:$B,0)) -> ﾌﾛｰﾊﾞﾙ | Q7: =IF(分類!B7="","",分類!B7) -> T14 | R7: =IF(Q7="","",_xlfn.XLOOKUP(Q7,大分類!$A:$A,大分類!$B:$B,0)) -> ｸﾞﾘｽﾆｯﾌﾟﾙ | S7: =IF(分類!D7="","",分類!D7) -> T19 | T7: =IF(S7="","",_xlfn.XLOOKUP(S7,中分類!$A:$A,中分類!$B:$B,0)) -> ﾒｯｷ | U7: =IF(分類!F7="","",分類!F7) -> T51 | V7: =IF(U7="","",_xlfn.XLOOKUP(U7,小分類!$A:$A,小分類!$B:$B,0)) -> ﾘﾘｰﾌﾆｯﾌﾟﾙ | Z7: =IF(分類!AN7="","",分類!AN7) -> 890 | AE7: =IF(分類!AM7="","",分類!AM7) -> 463 | AJ7: =IF(分類!AS7="","",分類!AS7) -> 0 | AO7: =IF(分類!AU7="","",分類!AU7) -> 694 | AT7: =IF(分類!AW7="","",分類!AW7) -> 0 | AY7: =IF(分類!AZ7="","",分類!AZ7) -> 0 | BD7: =IF(分類!BC7="","",分類!BC7) -> 0 | BI7: =IF(分類!BF7="","",分類!BF7) -> 0 | BN7: =IF(分類!BI7="","",分類!BI7) -> 0 | ER7: =IF(分類!H7="","",分類!H7) -> 1 | ES7: =IF(ER7="","",_xlfn.XLOOKUP(提出用書式!ER7,在庫取寄区分!$A:$A,在庫取寄区分!$B:$B,0)) -> 常時在庫品 | ET7: =IF(分類!BV7="","",分類!BV7) | EW7: =IF(分類!BW7="","",分類!BW7) | EX7: =IF(分類!BX7="","",分類!BX7) | FB7: =IF(分類!BY7="","",分類!BY7)

Sheet 大分類
A1: ｺｰﾄﾞ | B1: 分類名
A2: T1 | B2: ﾎｰｽ継手
A3: T2 | B3: 配管継手
A4: T3 | B4: 銅管継手
A5: T4 | B5: ﾈｼﾞ継手
A6: T5 | B6: ﾌﾗﾝｼﾞ
A7: T6 | B7: 溶接継手
A8: T7 | B8: 高圧継手
A9: T8 | B9: 空圧継手
A10: T9 | B10: ｸｲｺﾐ継手
A11: T10 | B11: 塩ﾋﾞ配管
A12: T11 | B12: 清水製作所
... A151: H43 | B151: 溶接棒：商品ｺｰﾄﾞ単位入力方法

Sheet 中分類
A1: ｺｰﾄﾞ | B1: 分類名
A2: A1 | B2: 右下精器
A3: A2 | B3: TOA(東亜ﾊﾞﾙﾌﾞ工業)
A4: Ｂ1 | B4: SCM435
A5: Ｂ2 | B5: SUS304
A6: Ｂ3 | B6: ﾕﾆｸﾛ
A7: Ｂ4 | B7: S45C(H)
A8: Ｂ5 | B8: S45C(H)ﾕﾆｸﾛ
A9: Ｂ6 | B9: SS鉄生地
A10: BE1 | B10: NSK(日本精工)
A11: BE2 | B11: 旭精工(ASAHI)
A12: C1 | B12: 三ﾂ星ﾍﾞﾙﾄ
... A136: T37 | B136: VU

Sheet 小分類
A1: ｺｰﾄﾞ | B1: 分類名
A2: A1 | B2: AT1/4X60
A3: A10 | B3: BT1/4RX60-
A4: A11 | B4: BT3/8RX75-
A5: A12 | B5: BT3/8RX100-
A6: A13 | B6: ﾒｰﾄﾙｺｯｸSUS
A7: A14 | B7: ﾒｰﾄﾙﾊﾟｲﾌﾟSUS
A8: A15 | B8: ﾒｰﾄﾙｺｯｸBC
A9: A2 | B9: AT3/8X75
A10: A3 | B10: AT3/8X100
A11: A4 | B11: BT1/4X60
A12: A5 | B12: BT3/8X75
... A488: BE112 | B488: 29400代M

Sheet 在庫取寄区分
A1: ｺｰﾄﾞ | B1: 在庫取寄区分
A2: 1 | B2: 常時在庫品
A3: 2 | B3: 取寄品
A4: 3 | B4: 価格表削除
A5: 4 | B5: 売切在庫品
A6: 5 | B6: 受注生産品

Sheet ﾒｰｶｰCD
A1: ｺｰﾄﾞ | B1: ﾒｰｶｰ
A2: 972038 | B2: 三ﾂ星
A3: 963161 | B3: ﾌﾛｰﾊﾞﾙ
A4: 963127 | B4: FKK
A5: 1 | B5: ﾅｺﾞﾔ
A6: 2 | B6: ｱﾑﾄ
A7: F1 | B7: ｻﾝｺｰﾃｸﾉ
A8: 952249 | B8: 日本ﾃﾞｺﾗ
A9: 952072 | B9: ﾆｯﾀ･ﾑｱｰ
A10: 3 | B10: ｲﾉｯｸ
A11: T32 | B11: ｽｲｺｰ
A12: T15 | B12: 三興ﾏﾃﾘｱﾙｻﾌﾟﾗｲ
A13: 934021 | B13: ｴｽﾛﾝ
A14: 943007 | C14: SUS溶接ﾌﾗﾝｼﾞ
A15: 911069 | B15: ASAHI | C15: 旭精工
A16: 922022 | B16: KITZ
A17: 943013 | B17: 椿本ﾁｴｲﾝ
A18: 952143 | B18: 日本精工 | C18: NSK
A19: 000004 | B19: ｶﾈﾐﾂ
A20: 000008 | B20: TOYO
A21: K21 | B21: OSG
A22: 963042 | B22: NACHI
A23: 932263 | B23: 昭和ｺｰﾎﾟﾚｰｼｮﾝ
A24: 911037 | B24: ｱｶｷﾞ
A25: 4 | B25: 前田工繊
A26: 914083 | B26: NOK
A27: 911166 | B27: 旭有機材
A28: 932023 | B28: CKD
A29: 945058 | B29: TOHO

Sheet 単位CD
A1: ｺｰﾄﾞ | B1: 単位
A2: 01 | B2: ヶ
A3: 02 | B3: 本
A4: 03 | B4: S
A5: 04 | B5: P
A6: 05 | B6: 巻
A7: 06 | B7: 箱
A8: 07 | B8: 式
A9: 08 | B9: 台
A10: 09 | B10: 枚
A11: 10 | B11: M
A12: 11 | B12: kg
... A17: 16 | B17: 缶
A18: 17
A19: 18
A20: 19 | B20: 打
A21: 20 | B21: 名
A22: 21
A23: 22 | B23: 着
A24: 23 | B24: 袋
A25: 24 | B25: 基
A26: 25 | B26: 棟
A27: 26 | B27: 足
A28: 27 | B28: 丁
A29: 28 | B29: 組
A30: 29 | B30: 冊
A31: 30 | B31: h
A32: 31 | B32: PK

Sheet 仕入先CD
A1: ｺｰﾄﾞ | B1: 仕入先
A2: 1 | B2: 暁鋲螺
A3: 2 | B3: ｱﾏﾀﾞﾏｼﾅﾘｰ
A4: 3 | B4: 粟井機鋼
A5: 4 | B5: 三有研器
A6: 5 | B6: IZUSHI
A7: 6 | B7: いけうち
A8: 7 | B8: 丸晋
A9: 8 | B9: 椿広告社
A10: 9 | B10: 日本電化工業所
A11: 10 | B11: 伊藤鐵工所
A12: 11 | B12: 梅田機工
A13: 12 | B13: ｺｰｴｲ工業
... A64: 63 | B64: 塩屋
A65: 64
A66: 65 | B66: ｴｽﾌﾞｲｴﾌ
A67: 66 | B67: 杉本商事
A68: 67 | B68: 住ｺﾞﾑ産業
A69: 68 | B69: 瀬戸内ｽﾘｰﾎﾞﾝﾄﾞ
A70: 69 | B70: ｾｲﾌﾞ
A71: 70 | B71: 尼崎工作所
A72: 71 | B72: 西日本ｾｷｽｲ
A73: 72 | B73: ｾｷｾﾞﾝ
A74: 73
A75: 74 | B75: ﾀｲｶﾜ商事
A76: 75 | B76: 第一精機ｴﾝｼﾞﾆｱﾘﾝｸﾞ
A77: 76 | B77: ﾀｷｹﾞﾝ製造
A78: 77 | B78: ﾀﾞｲｹﾝ
A79: 78 | B79: 大喜産業
A80: 79 | B80: 大和住宅ｻﾞｰﾋﾞｽ
A81: 80 | B81: 千代田組
A82: 81 | B82: 鶴見製作所
A83: 82 | B83: ﾃｲｴﾙﾌﾞｲ
A84: 83 | B84: 東邦産業
A85: 84 | B85: 豊嶋商店
A86: 85
A87: 86 | B87: 酉島製作所
A88: 87 | B88: 東洋ｺﾞﾑ加工品販売
A89: 88 | B89: 東豊商事
A90: 89 | B90: 銅山川上水道管工事
...

Sheet お客様CD
A1: ｺｰﾄﾞ | B1: 仕入先
A2: 1 | B2: 三和金属
A3: 3 | B3: ｱｲﾑ
A4: 4 | B4: 井原鉄工所
A5: 5 | B5: 井原鉄工所 山田井
A6: 6 | B6: 伊予機械
A7: 7 | B7: ｻﾄｰｴﾝｼﾞ
A8: 8 | B8: ㈱SGM
A9: 9 | B9: ｳﾀﾞｶｴﾝｼﾞ
A10: 10 | B10: ㈱SGM 物件
A11: 11 | B11: ｴﾋﾒ紙工
A12: 12 | B12: ｵｰｸﾗ製紙
A13: 13 | B13: ㈱越智技研工業
... A359: 385 | B359: 尾藤建設
A360: 386
A361: 387 | B361: 出光ﾘﾃｰﾙ販売
A362: 388 | B362: 四国中央病院
A363: 389 | B363: 曽我部建設
A364: 390 | B364: ﾒｶﾃｯｸ
A365: 392 | B365: 株式会社ｱｲﾜ
A366: 393 | B366: 二葉電気株式会社
A367: 394 | B367: 大西物流株式会社
A368: 395 | B368: 森川㈱
A369: 396 | B369: 一宮運輸株式会社
A370: 397 | B370: 四国紙販売
A371: 398 | B371: 日本GEｷｬﾋﾟﾀﾙ
A372: 399 | B372: 高知歯車
... A374: 401 | B374: 四国中央市役所
A375: 402
A376: 403 | B376: ｴﾘｴｰﾙﾍﾟｰﾊﾟｰﾃｸﾉ
A377: 404 | B377: ﾀﾞｲｵｰﾍﾟｰﾊﾟｰﾃｯｸ
A378: 405 | B378: ﾀﾞｲｵｰｴｺﾜｰｸ
A379: 406 | B379: ｴﾘｴｰﾙﾌﾟﾛﾀﾞｸﾄ
A380: 407 | B380: ﾀﾞｲｵｰｴﾝｼﾞ一課
A381: 408 | B381: 大王製紙
A382: 409 | B382: (有)ﾔﾏﾌﾞﾗ
A383: 410 | B383: ｶﾀｵｶｷｺｰ
A384: 411 | B384: 尾木製缶所
A385: 412 | B385: 共和自動車商会
A386: 413 | B386: ｼﾝﾜ
...
